<?xml version="1.0" encoding="UTF-8"?>
<testng-results ignored="0" total="2" passed="1" failed="1" skipped="0">
  <reporter-output>
  </reporter-output>
  <suite started-at="2022-12-23T15:28:03 IST" name="Default suite" finished-at="2022-12-23T15:28:03 IST" duration-ms="206">
    <groups>
    </groups>
    <test started-at="2022-12-23T15:28:03 IST" name="Default test" finished-at="2022-12-23T15:28:03 IST" duration-ms="206">
      <class name="testCase.TestN">
        <test-method signature="WicketKeeper()[pri:0, instance:testCase.TestN@2473d930]" started-at="2022-12-23T15:28:03 IST" name="WicketKeeper" finished-at="2022-12-23T15:28:03 IST" duration-ms="75" status="PASS">
          <reporter-output>
          </reporter-output>
        </test-method> <!-- WicketKeeper -->
        <test-method signature="forignPlayer()[pri:0, instance:testCase.TestN@2473d930]" started-at="2022-12-23T15:28:03 IST" name="forignPlayer" finished-at="2022-12-23T15:28:03 IST" duration-ms="16" status="FAIL">
          <exception class="java.lang.AssertionError">
            <message>
              <![CDATA[The following asserts failed:
Test is fail as we have forign player more than 4]]>
            </message>
            <full-stacktrace>
              <![CDATA[java.lang.AssertionError: The following asserts failed:
Test is fail as we have forign player more than 4
at org.testng.asserts.SoftAssert.assertAll(SoftAssert.java:47)
at org.testng.asserts.SoftAssert.assertAll(SoftAssert.java:31)
at testCase.TestN.forignPlayer(TestN.java:22)
at java.base/jdk.internal.reflect.DirectMethodHandleAccessor.invoke(DirectMethodHandleAccessor.java:104)
at java.base/java.lang.reflect.Method.invoke(Method.java:577)
at org.testng.internal.MethodInvocationHelper.invokeMethod(MethodInvocationHelper.java:133)
at org.testng.internal.TestInvoker.invokeMethod(TestInvoker.java:584)
at org.testng.internal.TestInvoker.invokeTestMethod(TestInvoker.java:172)
at org.testng.internal.MethodRunner.runInSequence(MethodRunner.java:46)
at org.testng.internal.TestInvoker$MethodInvocationAgent.invoke(TestInvoker.java:804)
at org.testng.internal.TestInvoker.invokeTestMethods(TestInvoker.java:145)
at org.testng.internal.TestMethodWorker.invokeTestMethods(TestMethodWorker.java:146)
at org.testng.internal.TestMethodWorker.run(TestMethodWorker.java:128)
at java.base/java.util.ArrayList.forEach(ArrayList.java:1511)
at org.testng.TestRunner.privateRun(TestRunner.java:770)
at org.testng.TestRunner.run(TestRunner.java:591)
at org.testng.SuiteRunner.runTest(SuiteRunner.java:402)
at org.testng.SuiteRunner.runSequentially(SuiteRunner.java:396)
at org.testng.SuiteRunner.privateRun(SuiteRunner.java:355)
at org.testng.SuiteRunner.run(SuiteRunner.java:304)
at org.testng.SuiteRunnerWorker.runSuite(SuiteRunnerWorker.java:53)
at org.testng.SuiteRunnerWorker.run(SuiteRunnerWorker.java:96)
at org.testng.TestNG.runSuitesSequentially(TestNG.java:1180)
at org.testng.TestNG.runSuitesLocally(TestNG.java:1102)
at org.testng.TestNG.runSuites(TestNG.java:1032)
at org.testng.TestNG.run(TestNG.java:1000)
at org.testng.remote.AbstractRemoteTestNG.run(AbstractRemoteTestNG.java:115)
at org.testng.remote.RemoteTestNG.initAndRun(RemoteTestNG.java:251)
at org.testng.remote.RemoteTestNG.main(RemoteTestNG.java:77)
]]>
            </full-stacktrace>
          </exception> <!-- java.lang.AssertionError -->
          <reporter-output>
          </reporter-output>
        </test-method> <!-- forignPlayer -->
      </class> <!-- testCase.TestN -->
    </test> <!-- Default test -->
  </suite> <!-- Default suite -->
</testng-results>
